Workbook
Name Audit_ID: REFINED_DATA!$A$1:$I$51
Name Slicer_Week_Ending: #N/A

Sheet DASHBOARD
B1: LOAN PROCESSING QUALITY — WEEKLY PERFORMANCE DASHBOARD
B2: =TODAY() -> 46247
B4: TEAM ACCURACY | D4: TOTAL AUDITS | F4: SLA ADHERENCE | H4: TOTAL ERRORS
B5: =GETPIVOTDATA("Accuracy_Rate",PIVOT_ACCURACY!$A$3) -> 0.81818182 | D5: =GETPIVOTDATA("Total_Audits",PIVOT_ACCURACY!$A$3) -> 55 | F5: =COUNTIF(REFINED_DATA!I:I,"Met")/COUNTA(REFINED_DATA!A1:A51) -> 0.84313725 | H5: =COUNTIF(REFINED_DATA!E:E,0) -> 10
B7: Target: 85% | D7: Cases This Period | F7: Target: 80% | H7: Of 50 Audits This Period
B8: =IF(B5>=0.92,"✅ On Track","⚠ Below Target") -> ⚠ Below Target | D8: ✅ Audit Met | F8: =IF(F5>=80%,"✅ On Track","⚠ Below Target") -> ✅ On Track | H8: =H5 & " errors ("&TEXT(H5/50,"0%")&" error rate)" -> 10 errors (20% error rate)
B10: ANALYST PERFORMANCE SUMMARY
B11: Analyst | C11: Accuracy | D11: SLA Rate | E11: Errors | F11: Status
B12: Priya Sharma | C12: =AVERAGEIF(REFINED_DATA!C:C,DASHBOARD!B12,REFINED_DATA!E:E) -> 0.81818182 | D12: =COUNTIFS(REFINED_DATA!$C:$C,DASHBOARD!B12,REFINED_DATA!$I:$I,"Met")/COUNTIF(REFINED_DATA!$C:$C,DASHBOARD!B12) -> 0.90909091 | E12: =IFERROR(COUNTIFS(REFINED_DATA!$C:$C,DASHBOARD!B12,REFINED_DATA!$E:$E, 0)," ") -> 2 | F12: =IFERROR(IF(C12>=0.85,"✅ On Track","⚠ Review"),"") -> ⚠ Review
B13: Rohan Mehta | C13: =AVERAGEIF(REFINED_DATA!C:C,DASHBOARD!B13,REFINED_DATA!E:E) -> 0.9 | D13: =COUNTIFS(REFINED_DATA!$C:$C,DASHBOARD!B13,REFINED_DATA!$I:$I,"Met")/COUNTIF(REFINED_DATA!$C:$C,DASHBOARD!B13) -> 0.8 | E13: =IFERROR(COUNTIFS(REFINED_DATA!$C:$C,DASHBOARD!B13,REFINED_DATA!$E:$E, 0)," ") -> 1 | F13: =IFERROR(IF(C13>=0.85,"✅ On Track","⚠ Review"),"") -> ✅ On Track
B14: Sneha Patil | C14: =AVERAGEIF(REFINED_DATA!C:C,DASHBOARD!B14,REFINED_DATA!E:E) -> 0.69230769 | D14: =COUNTIFS(REFINED_DATA!$C:$C,DASHBOARD!B14,REFINED_DATA!$I:$I,"Met")/COUNTIF(REFINED_DATA!$C:$C,DASHBOARD!B14) -> 0.76923077 | E14: =IFERROR(COUNTIFS(REFINED_DATA!$C:$C,DASHBOARD!B14,REFINED_DATA!$E:$E, 0)," ") -> 4 | F14: =IFERROR(IF(C14>=0.85,"✅ On Track","⚠ Review"),"") -> ⚠ Review
B15: Karan Joshi | C15: =AVERAGEIF(REFINED_DATA!C:C,DASHBOARD!B15,REFINED_DATA!E:E) -> 0.9 | D15: =COUNTIFS(REFINED_DATA!$C:$C,DASHBOARD!B15,REFINED_DATA!$I:$I,"Met")/COUNTIF(REFINED_DATA!$C:$C,DASHBOARD!B15) -> 0.6 | E15: =IFERROR(COUNTIFS(REFINED_DATA!$C:$C,DASHBOARD!B15,REFINED_DATA!$E:$E, 0)," ") -> 1 | F15: =IFERROR(IF(C15>=0.85,"✅ On Track","⚠ Review"),"") -> ✅ On Track
B16: Meera Nair | C16: =AVERAGEIF(REFINED_DATA!C:C,DASHBOARD!B16,REFINED_DATA!E:E) -> 0.81818182 | D16: =COUNTIFS(REFINED_DATA!$C:$C,DASHBOARD!B16,REFINED_DATA!$I:$I,"Met")/COUNTIF(REFINED_DATA!$C:$C,DASHBOARD!B16) -> 0.81818182 | E16: =IFERROR(COUNTIFS(REFINED_DATA!$C:$C,DASHBOARD!B16,REFINED_DATA!$E:$E, 0)," ") -> 2 | F16: =IFERROR(IF(C16>=0.85,"✅ On Track","⚠ Review"),"") -> ⚠ Review
B18: TOP ERROR CATEGORIES
B19: Error Category | C19: Count | D19: % of Errors
B20: Document Error | C20: =IFERROR(COUNTIF(REFINED_DATA!$G:$G,DASHBOARD!B20),0) -> 3 | D20: =IFERROR(C20/SUM($C$20:$C$24),0) -> 0.3
B21: Calculation Error | C21: =IFERROR(COUNTIF(REFINED_DATA!$G:$G,DASHBOARD!B21),0) -> 3 | D21: =IFERROR(C21/SUM($C$20:$C$24),0) -> 0.3
B22: Policy Mismatch | C22: =IFERROR(COUNTIF(REFINED_DATA!$G:$G,DASHBOARD!B22),0) -> 2 | D22: =IFERROR(C22/SUM($C$20:$C$24),0) -> 0.2
B23: Compliance Error | C23: =IFERROR(COUNTIF(REFINED_DATA!$G:$G,DASHBOARD!B23),0) -> 1 | D23: =IFERROR(C23/SUM($C$20:$C$24),0) -> 0.1
B24: Data Entry Error | C24: =IFERROR(COUNTIF(REFINED_DATA!$G:$G,DASHBOARD!B24),0) -> 1 | D24: =IFERROR(C24/SUM($C$20:$C$24),0) -> 0.1
B26: AHT BY PROCESS TYPE
B27: Process Type | C27: Avg AHT | D27: Max AHT | E27: SLA Status
B28: Personal Loan | C28: =IFERROR(AVERAGEIF(REFINED_DATA!$D:$D,DASHBOARD!B28,REFINED_DATA!$H:$H),"0") -> 7.7631579 | D28: =IFERROR(_xlfn.MAXIFS(REFINED_DATA!$H:$H,REFINED_DATA!$D:$D,DASHBOARD!B28), "0") -> 12.5 | E28: =IF(C28<=8,"✅ SLA Met","⚠ Breached SLA") -> ✅ SLA Met
B29: Home Loan | C29: =IFERROR(AVERAGEIF(REFINED_DATA!$D:$D,DASHBOARD!B29,REFINED_DATA!$H:$H),"0") -> 7.8266667 | D29: =_xlfn.MAXIFS(REFINED_DATA!$H:$H,REFINED_DATA!$D:$D,DASHBOARD!B29) -> 10.5 | E29: =IF(C29<=8,"✅ SLA Met","⚠ Breached SLA") -> ✅ SLA Met
B30: MSME Loan | C30: =IFERROR(AVERAGEIF(REFINED_DATA!$D:$D,DASHBOARD!B30,REFINED_DATA!$H:$H),"0") -> 7.32 | D30: =_xlfn.MAXIFS(REFINED_DATA!$H:$H,REFINED_DATA!$D:$D,DASHBOARD!B30) -> 11 | E30: =IF(C30<=8,"✅ SLA Met","⚠ Breached SLA") -> ✅ SLA Met
B31: Gold Loan | C31: =IFERROR(AVERAGEIF(REFINED_DATA!$D:$D,DASHBOARD!B31,REFINED_DATA!$H:$H),"0") -> 8.1090909 | D31: =_xlfn.MAXIFS(REFINED_DATA!$H:$H,REFINED_DATA!$D:$D,DASHBOARD!B31) -> 11.2 | E31: =IF(C31<=8,"✅ SLA Met","⚠ SLA Breached") -> ⚠ SLA Breached
B33: SELECT WEEK TO FILTER ALL TABLES
B40: KEY INSIGHT
B41: ="Team Accuracy: "&TEXT(AVERAGEIF(REFINED_DATA!$C:$C,"<>",REFINED_DATA!$E:$E),"0.0%")& " | Errors this period: " &COUNTIF(REFINED_DATA!$E:$E,0) & " | SLA breaches: " &COUNTIF(REFINED_DATA!$I:$I,"Breached") -> Team Accuracy: 81.8% | Errors this period: 10 | SLA breaches: 12

Sheet RAW_DATA
A1: Audit_ID | B1: Audit_Date | C1: Week_Ending | D1: Analyst_Name | E1: Case_ID | F1: Process_Type | G1: Is_Correct | H1: Error_Category | I1: AHT_Minutes | J1: SLA_Met
A2: AUD-001 | B2: 02-Jun-26 | C2: 07-Jun-26 | D2: Priya Sharma | E2: LN-5001 | F2: Personal Loan | G2: 1 | I2: 6.5
A3: AUD-002 | B3: 02-Jun-26 | C3: 07-Jun-26 | D3: Rohan Mehta | E3: LN-5002 | F3: Home Loan | G3: 1 | I3: 9.2
A4: AUD-003 | B4: 03-Jun-26 | C4: 07-Jun-26 | D4: Sneha Patil | E4: LN-5003 | F4: MSME Loan | G4: 0 | H4: Document Error | I4: 7.8
A5: AUD-004 | B5: 03-Jun-26 | C5: 07-Jun-26 | D5: Karan Joshi | E5: LN-5004 | F5: Gold Loan | G5: 1 | I5: 5.5
A6: AUD-005 | B6: 04-Jun-26 | C6: 07-Jun-26 | D6: Meera Nair | E6: LN-5005 | F6: Personal Loan | G6: 1 | I6: 7.2
A7: AUD-006 | B7: 04-Jun-26 | C7: 07-Jun-26 | D7: Priya Sharma | E7: LN-5006 | F7: Personal Loan | G7: 0 | H7: Calculation Error | I7: 8.5
A8: AUD-007 | B8: 05-Jun-26 | C8: 07-Jun-26 | D8: Rohan Mehta | E8: LN-5007 | F8: Personal Loan | G8: 1 | I8: 6
A9: AUD-008 | B9: 05-Jun-26 | C9: 07-Jun-26 | D9: Sneha Patil | E9: LN-5008 | F9: Home Loan | G9: 1 | I9: 7.3
A10: AUD-009 | B10: 06-Jun-26 | C10: 07-Jun-26 | D10: Karan Joshi | E10: LN-5009 | F10: MSME Loan | G10: 1 | I10: 6.8
A11: AUD-010 | B11: 06-Jun-26 | C11: 07-Jun-26 | D11: Meera Nair | E11: LN-5010 | F11: Personal Loan | G11: 0 | H11: Policy Mismatch | I11: 6.2
A12: AUD-011 | B12: 08-Jun-26 | C12: 14-Jun-26 | D12: Priya Sharma | E12: LN-5011 | F12: Home Loan | G12: 1 | I12: 6.3
A13: AUD-012 | B13: 09-Jun-26 | C13: 14-Jun-26 | D13: Rohan Mehta | E13: LN-5012 | F13: MSME Loan | G13: 1 | I13: 7
A14: AUD-013 | B14: 09-Jun-26 | C14: 14-Jun-26 | D14: Sneha Patil | E14: LN-5013 | F14: Personal Loan | G14: 0 | H14: Document Error | I14: 6.5
A15: AUD-014 | B15: 10-Jun-26 | C15: 14-Jun-26 | D15: Karan Joshi | E15: LN-5014 | F15: Gold Loan | G15: 1 | I15: 8.2
A16: AUD-015 | B16: 10-Jun-26 | C16: 14-Jun-26 | D16: Meera Nair | E16: LN-5015 | F16: Home Loan | G16: 1 | I16: 7.6
A17: AUD-016 | B17: 11-Jun-26 | C17: 14-Jun-26 | D17: Priya Sharma | E17: LN-5016 | F17: Personal Loan | G17: 1 | I17: 6.5
A18: AUD-017 | B18: 12-Jun-26 | C18: 14-Jun-26 | D18: Rohan Mehta | E18: LN-5017 | F18: Gold Loan | G18: 0 | H18: Calculation Error | I18: 7.3
A19: AUD-018 | B19: 13-Jun-26 | C19: 14-Jun-26 | D19: Sneha Patil | E19: LN-5018 | F19: MSME Loan | G19: 1 | I19: 8.8
A20: AUD-019 | B20: 13-Jun-26 | C20: 14-Jun-26 | D20: Karan Joshi | E20: LN-5019 | F20: Personal Loan | G20: 1 | I20: 6.8
A21: AUD-020 | B21: 14-Jun-26 | C21: 14-Jun-26 | D21: Meera Nair | E21: LN-5020 | F21: Gold Loan | G21: 1 | I21: 8.2
A22: AUD-021 | B22: 15-Jun-26 | C22: 21-Jun-26 | D22: Priya Sharma | E22: LN-5021 | F22: MSME Loan | G22: 1 | I22: 5.8
A23: AUD-022 | B23: 15-Jun-26 | C23: 21-Jun-26 | D23: Rohan Mehta | E23: LN-5022 | F23: Home Loan | G23: 1 | I23: 6
A24: AUD-023 | B24: 16-Jun-26 | C24: 21-Jun-26 | D24: Sneha Patil | E24: LN-5023 | F24: Gold Loan | G24: 0 | H24: Compliance Error | I24: 7.1
A25: AUD-024 | B25: 16-Jun-26 | C25: 21-Jun-26 | D25: Karan Joshi | E25: LN-5024 | F25: Personal Loan | G25: 0 | H25: Document Error | I25: 9.2
A26: AUD-025 | B26: 17-Jun-26 | C26: 21-Jun-26 | D26: Meera Nair | E26: LN-5025 | F26: MSME Loan | G26: 1 | I26: 6
A27: AUD-026 | B27: 17-Jun-26 | C27: 21-Jun-26 | D27: Priya Sharma | E27: LN-5026 | F27: Home Loan | G27: 1 | I27: 7.5
A28: AUD-027 | B28: 18-Jun-26 | C28: 21-Jun-26 | D28: Rohan Mehta | E28: LN-5027 | F28: Personal Loan | G28: 1 | I28: 6.5
A29: AUD-028 | B29: 18-Jun-26 | C29: 21-Jun-26 | D29: Sneha Patil | E29: LN-5028 | F29: Gold Loan | G29: 0 | H29: Data Entry Error | I29: 9.5
A30: AUD-029 | B30: 19-Jun-26 | C30: 21-Jun-26 | D30: Karan Joshi | E30: LN-5029 | F30: Home Loan | G30: 1 | I30: 7.8
A31: AUD-030 | B31: 19-Jun-26 | C31: 21-Jun-26 | D31: Meera Nair | E31: LN-5030 | F31: Personal Loan | G31: 0 | H31: Calculation Error | I31: 10.2
A32: AUD-031 | B32: 20-Jun-26 | C32: 21-Jun-26 | D32: Priya Sharma | E32: LN-5031 | F32: Gold Loan | G32: 1 | I32: 6.8
A33: AUD-032 | B33: 20-Jun-26 | C33: 21-Jun-26 | D33: Rohan Mehta | E33: LN-5032 | F33: MSME Loan | G33: 1 | I33: 5.2
A34: AUD-033 | B34: 20-Jun-26 | C34: 21-Jun-26 | D34: Sneha Patil | E34: LN-5033 | F34: Personal Loan | G34: 1 | I34: 6.3
A35: AUD-034 | B35: 21-Jun-26 | C35: 21-Jun-26 | D35: Karan Joshi | E35: LN-5034 | F35: Home Loan | G35: 1 | I35: 10.5
A36: AUD-035 | B36: 21-Jun-26 | C36: 21-Jun-26 | D36: Priya Sharma | E36: LN-5035 | F36: Personal Loan | G36: 1 | I36: 7.3
A37: AUD-036 | B37: 21-Jun-26 | C37: 21-Jun-26 | D37: Meera Nair | E37: LN-5036 | F37: Gold Loan | G37: 1 | I37: 5.8
A38: AUD-037 | B38: 22-Jun-26 | C38: 28-Jun-26 | D38: Priya Sharma | E38: LN-5037 | F38: Home Loan | G38: 0 | H38: Policy Mismatch | I38: 7.6
A39: AUD-038 | B39: 22-Jun-26 | C39: 28-Jun-26 | D39: Rohan Mehta | E39: LN-5038 | F39: Personal Loan | G39: 1 | I39: 8.5
A40: AUD-039 | B40: 23-Jun-26 | C40: 28-Jun-26 | D40: Sneha Patil | E40: LN-5039 | F40: MSME Loan | G40: 1 | I40: 11
...

Sheet REFINED_DATA
A1: Audit_ID | B1: Week_Ending | C1: Analyst_Name | D1: Process_Type | E1: Is_Correct | F1: Accuracy_Flag | G1: Error_Category | H1: AHT_Minutes | I1: SLA_Met
A2: =RAW_DATA!A2 -> AUD-001 | B2: =RAW_DATA!C2 -> 07-Jun-26 | C2: =RAW_DATA!D2 -> Priya Sharma | D2: =RAW_DATA!F2 -> Personal Loan | E2: =RAW_DATA!G2 -> 1 | F2: =IFERROR(IF(RAW_DATA!G2=1,"Correct","Error")," ") -> Correct | G2: =IF(RAW_DATA!H2="","",RAW_DATA!H2) | H2: =RAW_DATA!I2 -> 6.5 | I2: =IFERROR(IF(RAW_DATA!I2<=8,"Met","Breached"),"") -> Met
A3: =RAW_DATA!A3 -> AUD-002 | B3: =RAW_DATA!C3 -> 07-Jun-26 | C3: =RAW_DATA!D3 -> Rohan Mehta | D3: =RAW_DATA!F3 -> Home Loan | E3: =RAW_DATA!G3 -> 1 | F3: =IFERROR(IF(RAW_DATA!G3=1,"Correct","Error")," ") -> Correct | G3: =IF(RAW_DATA!H3="","",RAW_DATA!H3) | H3: =RAW_DATA!I3 -> 9.2 | I3: =IFERROR(IF(RAW_DATA!I3<=8,"Met","Breached"),"") -> Breached
A4: =RAW_DATA!A4 -> AUD-003 | B4: =RAW_DATA!C4 -> 07-Jun-26 | C4: =RAW_DATA!D4 -> Sneha Patil | D4: =RAW_DATA!F4 -> MSME Loan | E4: =RAW_DATA!G4 -> 0 | F4: =IFERROR(IF(RAW_DATA!G4=1,"Correct","Error")," ") -> Error | G4: =IF(RAW_DATA!H4="","",RAW_DATA!H4) -> Document Error | H4: =RAW_DATA!I4 -> 7.8 | I4: =IFERROR(IF(RAW_DATA!I4<=8,"Met","Breached"),"") -> Met
A5: =RAW_DATA!A5 -> AUD-004 | B5: =RAW_DATA!C5 -> 07-Jun-26 | C5: =RAW_DATA!D5 -> Karan Joshi | D5: =RAW_DATA!F5 -> Gold Loan | E5: =RAW_DATA!G5 -> 1 | F5: =IFERROR(IF(RAW_DATA!G5=1,"Correct","Error")," ") -> Correct | G5: =IF(RAW_DATA!H5="","",RAW_DATA!H5) | H5: 7.5 | I5: =IFERROR(IF(RAW_DATA!I5<=8,"Met","Breached"),"") -> Met
A6: =RAW_DATA!A6 -> AUD-005 | B6: =RAW_DATA!C6 -> 07-Jun-26 | C6: =RAW_DATA!D6 -> Meera Nair | D6: =RAW_DATA!F6 -> Personal Loan | E6: =RAW_DATA!G6 -> 1 | F6: =IFERROR(IF(RAW_DATA!G6=1,"Correct","Error")," ") -> Correct | G6: =IF(RAW_DATA!H6="","",RAW_DATA!H6) | H6: =RAW_DATA!I6 -> 7.2 | I6: =IFERROR(IF(RAW_DATA!I6<=8,"Met","Breached"),"") -> Met
A7: =RAW_DATA!A7 -> AUD-006 | B7: =RAW_DATA!C7 -> 07-Jun-26 | C7: =RAW_DATA!D7 -> Priya Sharma | D7: =RAW_DATA!F7 -> Personal Loan | E7: =RAW_DATA!G7 -> 0 | F7: =IFERROR(IF(RAW_DATA!G7=1,"Correct","Error")," ") -> Error | G7: =IF(RAW_DATA!H7="","",RAW_DATA!H7) -> Calculation Error | H7: =RAW_DATA!I7 -> 8.5 | I7: =IFERROR(IF(RAW_DATA!I7<=8,"Met","Breached"),"") -> Breached
A8: =RAW_DATA!A8 -> AUD-007 | B8: =RAW_DATA!C8 -> 07-Jun-26 | C8: =RAW_DATA!D8 -> Rohan Mehta | D8: =RAW_DATA!F8 -> Personal Loan | E8: =RAW_DATA!G8 -> 1 | F8: =IFERROR(IF(RAW_DATA!G8=1,"Correct","Error")," ") -> Correct | G8: =IF(RAW_DATA!H8="","",RAW_DATA!H8) | H8: =RAW_DATA!I8 -> 6 | I8: =IFERROR(IF(RAW_DATA!I8<=8,"Met","Breached"),"") -> Met
A9: =RAW_DATA!A9 -> AUD-008 | B9: =RAW_DATA!C9 -> 07-Jun-26 | C9: =RAW_DATA!D9 -> Sneha Patil | D9: =RAW_DATA!F9 -> Home Loan | E9: =RAW_DATA!G9 -> 1 | F9: =IFERROR(IF(RAW_DATA!G9=1,"Correct","Error")," ") -> Correct | G9: =IF(RAW_DATA!H9="","",RAW_DATA!H9) | H9: =RAW_DATA!I9 -> 7.3 | I9: =IFERROR(IF(RAW_DATA!I9<=8,"Met","Breached"),"") -> Met
A10: =RAW_DATA!A10 -> AUD-009 | B10: =RAW_DATA!C10 -> 07-Jun-26 | C10: =RAW_DATA!D10 -> Karan Joshi | D10: =RAW_DATA!F10 -> MSME Loan | E10: =RAW_DATA!G10 -> 1 | F10: =IFERROR(IF(RAW_DATA!G10=1,"Correct","Error")," ") -> Correct | G10: =IF(RAW_DATA!H10="","",RAW_DATA!H10) | H10: =RAW_DATA!I10 -> 6.8 | I10: =IFERROR(IF(RAW_DATA!I10<=8,"Met","Breached"),"") -> Met
A11: =RAW_DATA!A11 -> AUD-010 | B11: =RAW_DATA!C11 -> 07-Jun-26 | C11: =RAW_DATA!D11 -> Meera Nair | D11: =RAW_DATA!F11 -> Personal Loan | E11: =RAW_DATA!G11 -> 0 | F11: =IFERROR(IF(RAW_DATA!G11=1,"Correct","Error")," ") -> Error | G11: =IF(RAW_DATA!H11="","",RAW_DATA!H11) -> Policy Mismatch | H11: =RAW_DATA!I11 -> 6.2 | I11: =IFERROR(IF(RAW_DATA!I11<=8,"Met","Breached"),"") -> Met
A12: =RAW_DATA!A12 -> AUD-011 | B12: =RAW_DATA!C12 -> 14-Jun-26 | C12: =RAW_DATA!D12 -> Priya Sharma | D12: =RAW_DATA!F12 -> Home Loan | E12: =RAW_DATA!G12 -> 1 | F12: =IFERROR(IF(RAW_DATA!G12=1,"Correct","Error")," ") -> Correct | G12: =IF(RAW_DATA!H12="","",RAW_DATA!H12) | H12: =RAW_DATA!I12 -> 6.3 | I12: =IFERROR(IF(RAW_DATA!I12<=8,"Met","Breached"),"") -> Met
A13: =RAW_DATA!A13 -> AUD-012 | B13: =RAW_DATA!C13 -> 14-Jun-26 | C13: =RAW_DATA!D13 -> Rohan Mehta | D13: =RAW_DATA!F13 -> MSME Loan | E13: =RAW_DATA!G13 -> 1 | F13: =IFERROR(IF(RAW_DATA!G13=1,"Correct","Error")," ") -> Correct | G13: =IF(RAW_DATA!H13="","",RAW_DATA!H13) | H13: =RAW_DATA!I13 -> 7 | I13: =IFERROR(IF(RAW_DATA!I13<=8,"Met","Breached"),"") -> Met
A14: =RAW_DATA!A14 -> AUD-013 | B14: =RAW_DATA!C14 -> 14-Jun-26 | C14: =RAW_DATA!D14 -> Sneha Patil | D14: =RAW_DATA!F14 -> Personal Loan | E14: =RAW_DATA!G14 -> 0 | F14: =IFERROR(IF(RAW_DATA!G14=1,"Correct","Error")," ") -> Error | G14: =IF(RAW_DATA!H14="","",RAW_DATA!H14) -> Document Error | H14: =RAW_DATA!I14 -> 6.5 | I14: =IFERROR(IF(RAW_DATA!I14<=8,"Met","Breached"),"") -> Met
A15: =RAW_DATA!A15 -> AUD-014 | B15: =RAW_DATA!C15 -> 14-Jun-26 | C15: =RAW_DATA!D15 -> Karan Joshi | D15: =RAW_DATA!F15 -> Gold Loan | E15: =RAW_DATA!G15 -> 1 | F15: =IFERROR(IF(RAW_DATA!G15=1,"Correct","Error")," ") -> Correct | G15: =IF(RAW_DATA!H15="","",RAW_DATA!H15) | H15: 10.2 | I15: =IFERROR(IF(RAW_DATA!I15<=8,"Met","Breached"),"") -> Breached
A16: =RAW_DATA!A16 -> AUD-015 | B16: =RAW_DATA!C16 -> 14-Jun-26 | C16: =RAW_DATA!D16 -> Meera Nair | D16: =RAW_DATA!F16 -> Home Loan | E16: =RAW_DATA!G16 -> 1 | F16: =IFERROR(IF(RAW_DATA!G16=1,"Correct","Error")," ") -> Correct | G16: =IF(RAW_DATA!H16="","",RAW_DATA!H16) | H16: =RAW_DATA!I16 -> 7.6 | I16: =IFERROR(IF(RAW_DATA!I16<=8,"Met","Breached"),"") -> Met
A17: =RAW_DATA!A17 -> AUD-016 | B17: =RAW_DATA!C17 -> 14-Jun-26 | C17: =RAW_DATA!D17 -> Priya Sharma | D17: =RAW_DATA!F17 -> Personal Loan | E17: =RAW_DATA!G17 -> 1 | F17: =IFERROR(IF(RAW_DATA!G17=1,"Correct","Error")," ") -> Correct | G17: =IF(RAW_DATA!H17="","",RAW_DATA!H17) | H17: =RAW_DATA!I17 -> 6.5 | I17: =IFERROR(IF(RAW_DATA!I17<=8,"Met","Breached"),"") -> Met
A18: =RAW_DATA!A18 -> AUD-017 | B18: =RAW_DATA!C18 -> 14-Jun-26 | C18: =RAW_DATA!D18 -> Rohan Mehta | D18: =RAW_DATA!F18 -> Gold Loan | E18: =RAW_DATA!G18 -> 0 | F18: =IFERROR(IF(RAW_DATA!G18=1,"Correct","Error")," ") -> Error | G18: =IF(RAW_DATA!H18="","",RAW_DATA!H18) -> Calculation Error | H18: =RAW_DATA!I18 -> 7.3 | I18: =IFERROR(IF(RAW_DATA!I18<=8,"Met","Breached"),"") -> Met
A19: =RAW_DATA!A19 -> AUD-018 | B19: =RAW_DATA!C19 -> 14-Jun-26 | C19: =RAW_DATA!D19 -> Sneha Patil | D19: =RAW_DATA!F19 -> MSME Loan | E19: =RAW_DATA!G19 -> 1 | F19: =IFERROR(IF(RAW_DATA!G19=1,"Correct","Error")," ") -> Correct | G19: =IF(RAW_DATA!H19="","",RAW_DATA!H19) | H19: 10.6 | I19: =IFERROR(IF(RAW_DATA!I19<=8,"Met","Breached"),"") -> Breached
A20: =RAW_DATA!A20 -> AUD-019 | B20: =RAW_DATA!C20 -> 14-Jun-26 | C20: =RAW_DATA!D20 -> Karan Joshi | D20: =RAW_DATA!F20 -> Personal Loan | E20: =RAW_DATA!G20 -> 1 | F20: =IFERROR(IF(RAW_DATA!G20=1,"Correct","Error")," ") -> Correct | G20: =IF(RAW_DATA!H20="","",RAW_DATA!H20) | H20: =RAW_DATA!I20 -> 6.8 | I20: =IFERROR(IF(RAW_DATA!I20<=8,"Met","Breached"),"") -> Met
A21: =RAW_DATA!A21 -> AUD-020 | B21: =RAW_DATA!C21 -> 14-Jun-26 | C21: =RAW_DATA!D21 -> Meera Nair | D21: =RAW_DATA!F21 -> Gold Loan | E21: =RAW_DATA!G21 -> 1 | F21: =IFERROR(IF(RAW_DATA!G21=1,"Correct","Error")," ") -> Correct | G21: =IF(RAW_DATA!H21="","",RAW_DATA!H21) | H21: =RAW_DATA!I21 -> 8.2 | I21: =IFERROR(IF(RAW_DATA!I21<=8,"Met","Breached"),"") -> Breached
A22: =RAW_DATA!A22 -> AUD-021 | B22: =RAW_DATA!C22 -> 21-Jun-26 | C22: =RAW_DATA!D22 -> Priya Sharma | D22: =RAW_DATA!F22 -> MSME Loan | E22: =RAW_DATA!G22 -> 1 | F22: =IFERROR(IF(RAW_DATA!G22=1,"Correct","Error")," ") -> Correct | G22: =IF(RAW_DATA!H22="","",RAW_DATA!H22) | H22: =RAW_DATA!I22 -> 5.8 | I22: =IFERROR(IF(RAW_DATA!I22<=8,"Met","Breached"),"") -> Met
A23: =RAW_DATA!A23 -> AUD-022 | B23: =RAW_DATA!C23 -> 21-Jun-26 | C23: =RAW_DATA!D23 -> Rohan Mehta | D23: =RAW_DATA!F23 -> Home Loan | E23: =RAW_DATA!G23 -> 1 | F23: =IFERROR(IF(RAW_DATA!G23=1,"Correct","Error")," ") -> Correct | G23: =IF(RAW_DATA!H23="","",RAW_DATA!H23) | H23: =RAW_DATA!I23 -> 6 | I23: =IFERROR(IF(RAW_DATA!I23<=8,"Met","Breached"),"") -> Met
A24: =RAW_DATA!A24 -> AUD-023 | B24: =RAW_DATA!C24 -> 21-Jun-26 | C24: =RAW_DATA!D24 -> Sneha Patil | D24: =RAW_DATA!F24 -> Gold Loan | E24: =RAW_DATA!G24 -> 0 | F24: =IFERROR(IF(RAW_DATA!G24=1,"Correct","Error")," ") -> Error | G24: =IF(RAW_DATA!H24="","",RAW_DATA!H24) -> Compliance Error | H24: =RAW_DATA!I24 -> 7.1 | I24: =IFERROR(IF(RAW_DATA!I24<=8,"Met","Breached"),"") -> Met
A25: =RAW_DATA!A25 -> AUD-024 | B25: =RAW_DATA!C25 -> 21-Jun-26 | C25: =RAW_DATA!D25 -> Karan Joshi | D25: =RAW_DATA!F25 -> Personal Loan | E25: =RAW_DATA!G25 -> 0 | F25: =IFERROR(IF(RAW_DATA!G25=1,"Correct","Error")," ") -> Error | G25: =IF(RAW_DATA!H25="","",RAW_DATA!H25) -> Document Error | H25: =RAW_DATA!I25 -> 9.2 | I25: =IFERROR(IF(RAW_DATA!I25<=8,"Met","Breached"),"") -> Breached
A26: =RAW_DATA!A26 -> AUD-025 | B26: =RAW_DATA!C26 -> 21-Jun-26 | C26: =RAW_DATA!D26 -> Meera Nair | D26: =RAW_DATA!F26 -> MSME Loan | E26: =RAW_DATA!G26 -> 1 | F26: =IFERROR(IF(RAW_DATA!G26=1,"Correct","Error")," ") -> Correct | G26: =IF(RAW_DATA!H26="","",RAW_DATA!H26) | H26: =RAW_DATA!I26 -> 6 | I26: =IFERROR(IF(RAW_DATA!I26<=8,"Met","Breached"),"") -> Met
A27: =RAW_DATA!A27 -> AUD-026 | B27: =RAW_DATA!C27 -> 21-Jun-26 | C27: =RAW_DATA!D27 -> Priya Sharma | D27: =RAW_DATA!F27 -> Home Loan | E27: =RAW_DATA!G27 -> 1 | F27: =IFERROR(IF(RAW_DATA!G27=1,"Correct","Error")," ") -> Correct | G27: =IF(RAW_DATA!H27="","",RAW_DATA!H27) | H27: =RAW_DATA!I27 -> 7.5 | I27: =IFERROR(IF(RAW_DATA!I27<=8,"Met","Breached"),"") -> Met
A28: =RAW_DATA!A28 -> AUD-027 | B28: =RAW_DATA!C28 -> 21-Jun-26 | C28: =RAW_DATA!D28 -> Rohan Mehta | D28: =RAW_DATA!F28 -> Personal Loan | E28: =RAW_DATA!G28 -> 1 | F28: =IFERROR(IF(RAW_DATA!G28=1,"Correct","Error")," ") -> Correct | G28: =IF(RAW_DATA!H28="","",RAW_DATA!H28) | H28: =RAW_DATA!I28 -> 6.5 | I28: =IFERROR(IF(RAW_DATA!I28<=8,"Met","Breached"),"") -> Met
A29: =RAW_DATA!A29 -> AUD-028 | B29: =RAW_DATA!C29 -> 21-Jun-26 | C29: =RAW_DATA!D29 -> Sneha Patil | D29: =RAW_DATA!F29 -> Gold Loan | E29: =RAW_DATA!G29 -> 0 | F29: =IFERROR(IF(RAW_DATA!G29=1,"Correct","Error")," ") -> Error | G29: =IF(RAW_DATA!H29="","",RAW_DATA!H29) -> Data Entry Error | H29: =RAW_DATA!I29 -> 9.5 | I29: =IFERROR(IF(RAW_DATA!I29<=8,"Met","Breached"),"") -> Breached
A30: =RAW_DATA!A30 -> AUD-029 | B30: =RAW_DATA!C30 -> 21-Jun-26 | C30: =RAW_DATA!D30 -> Karan Joshi | D30: =RAW_DATA!F30 -> Home Loan | E30: =RAW_DATA!G30 -> 1 | F30: =IFERROR(IF(RAW_DATA!G30=1,"Correct","Error")," ") -> Correct | G30: =IF(RAW_DATA!H30="","",RAW_DATA!H30) | H30: =RAW_DATA!I30 -> 7.8 | I30: =IFERROR(IF(RAW_DATA!I30<=8,"Met","Breached"),"") -> Met
A31: =RAW_DATA!A31 -> AUD-030 | B31: =RAW_DATA!C31 -> 21-Jun-26 | C31: =RAW_DATA!D31 -> Meera Nair | D31: =RAW_DATA!F31 -> Personal Loan | E31: =RAW_DATA!G31 -> 0 | F31: =IFERROR(IF(RAW_DATA!G31=1,"Correct","Error")," ") -> Error | G31: =IF(RAW_DATA!H31="","",RAW_DATA!H31) -> Calculation Error | H31: =RAW_DATA!I31 -> 10.2 | I31: =IFERROR(IF(RAW_DATA!I31<=8,"Met","Breached"),"") -> Breached
A32: =RAW_DATA!A32 -> AUD-031 | B32: =RAW_DATA!C32 -> 21-Jun-26 | C32: =RAW_DATA!D32 -> Priya Sharma | D32: =RAW_DATA!F32 -> Gold Loan | E32: =RAW_DATA!G32 -> 1 | F32: =IFERROR(IF(RAW_DATA!G32=1,"Correct","Error")," ") -> Correct | G32: =IF(RAW_DATA!H32="","",RAW_DATA!H32) | H32: 7.5 | I32: =IFERROR(IF(RAW_DATA!I32<=8,"Met","Breached"),"") -> Met
A33: =RAW_DATA!A33 -> AUD-032 | B33: =RAW_DATA!C33 -> 21-Jun-26 | C33: =RAW_DATA!D33 -> Rohan Mehta | D33: =RAW_DATA!F33 -> MSME Loan | E33: =RAW_DATA!G33 -> 1 | F33: =IFERROR(IF(RAW_DATA!G33=1,"Correct","Error")," ") -> Correct | G33: =IF(RAW_DATA!H33="","",RAW_DATA!H33) | H33: =RAW_DATA!I33 -> 5.2 | I33: =IFERROR(IF(RAW_DATA!I33<=8,"Met","Breached"),"") -> Met
A34: =RAW_DATA!A34 -> AUD-033 | B34: =RAW_DATA!C34 -> 21-Jun-26 | C34: =RAW_DATA!D34 -> Sneha Patil | D34: =RAW_DATA!F34 -> Personal Loan | E34: =RAW_DATA!G34 -> 1 | F34: =IFERROR(IF(RAW_DATA!G34=1,"Correct","Error")," ") -> Correct | G34: =IF(RAW_DATA!H34="","",RAW_DATA!H34) | H34: =RAW_DATA!I34 -> 6.3 | I34: =IFERROR(IF(RAW_DATA!I34<=8,"Met","Breached"),"") -> Met
A35: =RAW_DATA!A35 -> AUD-034 | B35: =RAW_DATA!C35 -> 21-Jun-26 | C35: =RAW_DATA!D35 -> Karan Joshi | D35: =RAW_DATA!F35 -> Home Loan | E35: =RAW_DATA!G35 -> 1 | F35: =IFERROR(IF(RAW_DATA!G35=1,"Correct","Error")," ") -> Correct | G35: =IF(RAW_DATA!H35="","",RAW_DATA!H35) | H35: =RAW_DATA!I35 -> 10.5 | I35: =IFERROR(IF(RAW_DATA!I35<=8,"Met","Breached"),"") -> Breached
A36: =RAW_DATA!A36 -> AUD-035 | B36: =RAW_DATA!C36 -> 21-Jun-26 | C36: =RAW_DATA!D36 -> Priya Sharma | D36: =RAW_DATA!F36 -> Personal Loan | E36: =RAW_DATA!G36 -> 1 | F36: =IFERROR(IF(RAW_DATA!G36=1,"Correct","Error")," ") -> Correct | G36: =IF(RAW_DATA!H36="","",RAW_DATA!H36) | H36: =RAW_DATA!I36 -> 7.3 | I36: =IFERROR(IF(RAW_DATA!I36<=8,"Met","Breached"),"") -> Met
A37: =RAW_DATA!A37 -> AUD-036 | B37: =RAW_DATA!C37 -> 21-Jun-26 | C37: =RAW_DATA!D37 -> Meera Nair | D37: =RAW_DATA!F37 -> Gold Loan | E37: =RAW_DATA!G37 -> 1 | F37: =IFERROR(IF(RAW_DATA!G37=1,"Correct","Error")," ") -> Correct | G37: =IF(RAW_DATA!H37="","",RAW_DATA!H37) | H37: 6.7 | I37: =IFERROR(IF(RAW_DATA!I37<=8,"Met","Breached"),"") -> Met
A38: =RAW_DATA!A38 -> AUD-037 | B38: =RAW_DATA!C38 -> 28-Jun-26 | C38: =RAW_DATA!D38 -> Priya Sharma | D38: =RAW_DATA!F38 -> Home Loan | E38: =RAW_DATA!G38 -> 0 | F38: =IFERROR(IF(RAW_DATA!G38=1,"Correct","Error")," ") -> Error | G38: =IF(RAW_DATA!H38="","",RAW_DATA!H38) -> Policy Mismatch | H38: =RAW_DATA!I38 -> 7.6 | I38: =IFERROR(IF(RAW_DATA!I38<=8,"Met","Breached"),"") -> Met
A39: =RAW_DATA!A39 -> AUD-038 | B39: =RAW_DATA!C39 -> 28-Jun-26 | C39: =RAW_DATA!D39 -> Rohan Mehta | D39: =RAW_DATA!F39 -> Personal Loan | E39: =RAW_DATA!G39 -> 1 | F39: =IFERROR(IF(RAW_DATA!G39=1,"Correct","Error")," ") -> Correct | G39: =IF(RAW_DATA!H39="","",RAW_DATA!H39) | H39: =RAW_DATA!I39 -> 8.5 | I39: =IFERROR(IF(RAW_DATA!I39<=8,"Met","Breached"),"") -> Breached
A40: =RAW_DATA!A40 -> AUD-039 | B40: =RAW_DATA!C40 -> 28-Jun-26 | C40: =RAW_DATA!D40 -> Sneha Patil | D40: =RAW_DATA!F40 -> MSME Loan | E40: =RAW_DATA!G40 -> 1 | F40: =IFERROR(IF(RAW_DATA!G40=1,"Correct","Error")," ") -> Correct | G40: =IF(RAW_DATA!H40="","",RAW_DATA!H40) | H40: =RAW_DATA!I40 -> 11 | I40: =IFERROR(IF(RAW_DATA!I40<=8,"Met","Breached"),"") -> Breached
...

Sheet PIVOT_ACCURACY
A1: Week_Ending | B1: (All)
A3: Analyst_Name | B3: Total_Audits | C3: Correct_Decisions | D3: Accuracy_Rate | E3: SLA Status (Target: 92%)
A4: Karan Joshi | B4: 10 | C4: 9 | D4: 0.9 | E4: =IF(D4>=85%, "✅ Meeting SLA", "⚠ Below Target") -> ✅ Meeting SLA
A5: Meera Nair | B5: 11 | C5: 9 | D5: 0.81818182 | E5: =IF(D5>=85%, "✅ Meeting SLA", "⚠ Below Target") -> ⚠ Below Target
A6: Priya Sharma | B6: 11 | C6: 9 | D6: 0.81818182 | E6: =IF(D6>=85%, "✅ Meeting SLA", "⚠ Below Target") -> ⚠ Below Target
A7: Rohan Mehta | B7: 10 | C7: 9 | D7: 0.9 | E7: =IF(D7>=85%, "✅ Meeting SLA", "⚠ Below Target") -> ✅ Meeting SLA
A8: Sneha Patil | B8: 13 | C8: 9 | D8: 0.69230769 | E8: =IF(D8>=85%, "✅ Meeting SLA", "⚠ Below Target") -> ⚠ Below Target
A9: Grand Total | B9: 55 | C9: 45 | D9: 0.81818182

Sheet PIVOT_ERRORS
A1: Week_Ending | B1: (All) | F1: ERROR BREAKDOWN BY ANALYST
A3: Error_Category | B3: Error_Count | C3: % of Total Errors | D3: Cumulative % | G3: Priya Sharma | H3: Rohan Mehta | I3: Sneha Patil | J3: Karan Joshi | K3: Meera Nair | L3: Total
A4: Document Error | B4: 3 | C4: =B4/SUM($B$4:$B$8) -> 0.3 | D4: =C4 -> 0.3 | F4: Document Error | G4: =COUNTIFS(REFINED_DATA!$C:$C,PIVOT_ERRORS!G$3,REFINED_DATA!$G:$G,PIVOT_ERRORS!$F4) -> 0 | H4: =COUNTIFS(REFINED_DATA!$C:$C,PIVOT_ERRORS!H$3,REFINED_DATA!$G:$G,PIVOT_ERRORS!$F4) -> 0 | I4: =COUNTIFS(REFINED_DATA!$C:$C,PIVOT_ERRORS!I$3,REFINED_DATA!$G:$G,PIVOT_ERRORS!$F4) -> 2 | J4: =COUNTIFS(REFINED_DATA!$C:$C,PIVOT_ERRORS!J$3,REFINED_DATA!$G:$G,PIVOT_ERRORS!$F4) -> 1 | K4: =COUNTIFS(REFINED_DATA!$C:$C,PIVOT_ERRORS!K$3,REFINED_DATA!$G:$G,PIVOT_ERRORS!$F4) -> 0 | L4: =SUM(G4:K4) -> 3
A5: Calculation Error | B5: 3 | C5: =B5/SUM($B$4:$B$8) -> 0.3 | D5: =D4+C5 -> 0.6 | F5: Calculation Error | G5: =COUNTIFS(REFINED_DATA!$C:$C,PIVOT_ERRORS!G$3,REFINED_DATA!$G:$G,PIVOT_ERRORS!$F5) -> 1 | H5: =COUNTIFS(REFINED_DATA!$C:$C,PIVOT_ERRORS!H$3,REFINED_DATA!$G:$G,PIVOT_ERRORS!$F5) -> 1 | I5: =COUNTIFS(REFINED_DATA!$C:$C,PIVOT_ERRORS!I$3,REFINED_DATA!$G:$G,PIVOT_ERRORS!$F5) -> 0 | J5: =COUNTIFS(REFINED_DATA!$C:$C,PIVOT_ERRORS!J$3,REFINED_DATA!$G:$G,PIVOT_ERRORS!$F5) -> 0 | K5: =COUNTIFS(REFINED_DATA!$C:$C,PIVOT_ERRORS!K$3,REFINED_DATA!$G:$G,PIVOT_ERRORS!$F5) -> 1 | L5: =SUM(G5:K5) -> 3
A6: Policy Mismatch | B6: 2 | C6: =B6/SUM($B$4:$B$8) -> 0.2 | D6: =D5+C6 -> 0.8 | F6: Policy Mismatch | G6: =COUNTIFS(REFINED_DATA!$C:$C,PIVOT_ERRORS!G$3,REFINED_DATA!$G:$G,PIVOT_ERRORS!$F6) -> 1 | H6: =COUNTIFS(REFINED_DATA!$C:$C,PIVOT_ERRORS!H$3,REFINED_DATA!$G:$G,PIVOT_ERRORS!$F6) -> 0 | I6: =COUNTIFS(REFINED_DATA!$C:$C,PIVOT_ERRORS!I$3,REFINED_DATA!$G:$G,PIVOT_ERRORS!$F6) -> 0 | J6: =COUNTIFS(REFINED_DATA!$C:$C,PIVOT_ERRORS!J$3,REFINED_DATA!$G:$G,PIVOT_ERRORS!$F6) -> 0 | K6: =COUNTIFS(REFINED_DATA!$C:$C,PIVOT_ERRORS!K$3,REFINED_DATA!$G:$G,PIVOT_ERRORS!$F6) -> 1 | L6: =SUM(G6:K6) -> 2
A7: Compliance Error | B7: 1 | C7: =B7/SUM($B$4:$B$8) -> 0.1 | D7: =D6+C7 -> 0.9 | F7: Compliance Error | G7: =COUNTIFS(REFINED_DATA!$C:$C,PIVOT_ERRORS!G$3,REFINED_DATA!$G:$G,PIVOT_ERRORS!$F7) -> 0 | H7: =COUNTIFS(REFINED_DATA!$C:$C,PIVOT_ERRORS!H$3,REFINED_DATA!$G:$G,PIVOT_ERRORS!$F7) -> 0 | I7: =COUNTIFS(REFINED_DATA!$C:$C,PIVOT_ERRORS!I$3,REFINED_DATA!$G:$G,PIVOT_ERRORS!$F7) -> 1 | J7: =COUNTIFS(REFINED_DATA!$C:$C,PIVOT_ERRORS!J$3,REFINED_DATA!$G:$G,PIVOT_ERRORS!$F7) -> 0 | K7: =COUNTIFS(REFINED_DATA!$C:$C,PIVOT_ERRORS!K$3,REFINED_DATA!$G:$G,PIVOT_ERRORS!$F7) -> 0 | L7: =SUM(G7:K7) -> 1
A8: Data Entry Error | B8: 1 | C8: =B8/SUM($B$4:$B$8) -> 0.1 | D8: =D7+C8 -> 1 | F8: Data Entry Error | G8: =COUNTIFS(REFINED_DATA!$C:$C,PIVOT_ERRORS!G$3,REFINED_DATA!$G:$G,PIVOT_ERRORS!$F8) -> 0 | H8: =COUNTIFS(REFINED_DATA!$C:$C,PIVOT_ERRORS!H$3,REFINED_DATA!$G:$G,PIVOT_ERRORS!$F8) -> 0 | I8: =COUNTIFS(REFINED_DATA!$C:$C,PIVOT_ERRORS!I$3,REFINED_DATA!$G:$G,PIVOT_ERRORS!$F8) -> 1 | J8: =COUNTIFS(REFINED_DATA!$C:$C,PIVOT_ERRORS!J$3,REFINED_DATA!$G:$G,PIVOT_ERRORS!$F8) -> 0 | K8: =COUNTIFS(REFINED_DATA!$C:$C,PIVOT_ERRORS!K$3,REFINED_DATA!$G:$G,PIVOT_ERRORS!$F8) -> 0 | L8: =SUM(G8:K8) -> 1
A9: Grand Total | B9: 10 | C9: =SUM(C4:C8) -> 1 | F9: Total | G9: =SUM(G4:G8) -> 2 | H9: =SUM(H4:H8) -> 1 | I9: =SUM(I4:I8) -> 4 | J9: =SUM(J4:J8) -> 1 | K9: =SUM(K4:K8) -> 2 | L9: =SUM(G9:K9) -> 10

Sheet PIVOT_SLA
A1: Week_Ending | B1: (All)
A3: Cases | B3: SLA_Status
A4: Analyst_Name | B4: Breached | C4: Met | D4: Grand Total | F4: SLA Adherence Rate | G4: Avg AHT (mins) | H4: vs Target
A5: Karan Joshi | B5: 4 | C5: 6 | D5: 10 | F5: =COUNTIFS(REFINED_DATA!$C:$C,PIVOT_SLA!$A5,REFINED_DATA!$I:$I,"Met")/COUNTIF(REFINED_DATA!$C:$C,PIVOT_SLA!$A5) -> 0.6 | G5: =AVERAGEIF(REFINED_DATA!$C:$C,PIVOT_SLA!A5,REFINED_DATA!$H:$H) -> 8.43 | H5: =IF(G5<=8,"✅ Within target","⚠ Above target") -> ⚠ Above target
A6: Meera Nair | B6: 2 | C6: 9 | D6: 11 | F6: =COUNTIFS(REFINED_DATA!$C:$C,PIVOT_SLA!$A6,REFINED_DATA!$I:$I,"Met")/COUNTIF(REFINED_DATA!$C:$C,PIVOT_SLA!$A6) -> 0.81818182 | G6: =AVERAGEIF(REFINED_DATA!$C:$C,PIVOT_SLA!A6,REFINED_DATA!$H:$H) -> 8.1545455 | H6: =IF(G6<=8,"✅ Within target","⚠ Above target") -> ⚠ Above target
A7: Priya Sharma | B7: 1 | C7: 10 | D7: 11 | F7: =COUNTIFS(REFINED_DATA!$C:$C,PIVOT_SLA!$A7,REFINED_DATA!$I:$I,"Met")/COUNTIF(REFINED_DATA!$C:$C,PIVOT_SLA!$A7) -> 0.90909091 | G7: =AVERAGEIF(REFINED_DATA!$C:$C,PIVOT_SLA!A7,REFINED_DATA!$H:$H) -> 6.8363636 | H7: =IF(G7<=8,"✅ Within target","⚠ Above target") -> ✅ Within target
A8: Rohan Mehta | B8: 2 | C8: 8 | D8: 10 | F8: =COUNTIFS(REFINED_DATA!$C:$C,PIVOT_SLA!$A8,REFINED_DATA!$I:$I,"Met")/COUNTIF(REFINED_DATA!$C:$C,PIVOT_SLA!$A8) -> 0.8 | G8: =AVERAGEIF(REFINED_DATA!$C:$C,PIVOT_SLA!A8,REFINED_DATA!$H:$H) -> 6.95 | H8: =IF(G8<=8,"✅ Within target","⚠ Above target") -> ✅ Within target
A9: Sneha Patil | B9: 3 | C9: 10 | D9: 13 | F9: =COUNTIFS(REFINED_DATA!$C:$C,PIVOT_SLA!$A9,REFINED_DATA!$I:$I,"Met")/COUNTIF(REFINED_DATA!$C:$C,PIVOT_SLA!$A9) -> 0.76923077 | G9: =AVERAGEIF(REFINED_DATA!$C:$C,PIVOT_SLA!A9,REFINED_DATA!$H:$H) -> 8.3538462 | H9: =IF(G9<=8,"✅ Within target","⚠ Above target") -> ⚠ Above target
A10: Grand Total | B10: 12 | C10: 43 | D10: 55 | F10: Team SLA Target | G10: 8
F11: Team Average AHT | G11: =AVERAGEIF(REFINED_DATA!$C:$C,"<>",REFINED_DATA!$H:$H) -> 7.7690909 | H11: =IF(G11<8,"✅ Within target","⚠ Above target") -> ✅ Within target
A13: SLA ADHERENCE BY ANALYST
A17: Process_Type | B17: Total_Cases | C17: Avg_AHT | D17: Max_AHT | E17: SLA Status
A18: Gold Loan | B18: 11 | C18: 8.1090909 | D18: 11.2 | E18: =IF(C18<=8,"✅ Within target","⚠ Above target") -> ⚠ Above target
A19: Home Loan | B19: 15 | C19: 7.8266667 | D19: 10.5 | E19: =IF(C19<=8,"✅ Within target","⚠ Above target") -> ✅ Within target
A20: MSME Loan | B20: 10 | C20: 7.32 | D20: 11 | E20: =IF(C20<=8,"✅ Within target","⚠ Above target") -> ✅ Within target
A21: Personal Loan | B21: 19 | C21: 7.7631579 | D21: 12.5 | E21: =IF(C21<=8,"✅ Within target","⚠ Above target") -> ✅ Within target
A22: Grand Total | B22: 55 | C22: 7.7690909 | D22: 12.5 | E22: =IF(C22<=8,"✅ Within target","⚠ Above target") -> ✅ Within target
A24: AHT BY PROCESS
